Workbook

Sheet Dashboard
B1: Rehabilitation Dashboard | M1: LEEDS UNITED ACADEMY · SPORTS MEDICINE
B4: PLAYER | E4: POSITION · SQUAD | G4: INJURY / DIAGNOSIS | K4: INJURED SIDE | L4: INJURY DATE | N4: WEEK OF REHAB | P4: EXPECTED RTP
B5: Example Player | E5: CM · U16 | G5: e.g. L ACL reconstruction | K5: L | L5: 46244 | N5: =IF($L$5="","",INT((TODAY()-$L$5)/7)+1) -> 11 | P5: 46419
B7: DOB | C7: AGE (YRS) | D7: AGE AT INJURY | E7: HEIGHT (CM) | G7: BODY MASS (KG) | I7: MAT. OFFSET | K7: MATURITY | L7: % PAH | N7: MEASURED ON | P7: DAYS POST INJURY
B8: 40616 | C8: =IF(B8="","",(TODAY()-B8)/365.25) -> 15.605749 | D8: =IF(OR(B8="",$L$5=""),"",($L$5-B8)/365.25) -> 15.408624 | E8: 171.4 | G8: 58.2 | I8: 0.6 | K8: =IF(L8<>"",IF(IF(L8<=1.5,L8*100,L8)<85,"Pre-PHV",IF(IF(L8<=1.5,L8*100,L8)<=95,"Circa-PHV","Post-PHV")),IF(I8<>"",IF(I8<-1,"Pre-PHV",IF(I8<=1,"Circa-PHV","Post-PHV")),"")) -> Circa-PHV | N8: 46266 | P8: =IF($L$5="","",TODAY()-$L$5) -> 72
B9: Maturity: % predicted adult height (PAH) if entered — <85% pre · 85–95% circa · >95% post — otherwise maturity offset (< −1 pre · −1 to +1 circa · > +1 post).
B11: Current status
B12: AVAILABILITY | K12: CURRENT FOCUS
B13: ='Dash Feed'!$B$15 -> Unavailable — training & fixtures | K13: ='Dash Feed'!$B$16 -> Pitch-based — linear running / volume focus + accel/decel
B14: =IF('Dash Feed'!$B$18="","Set availability and focus on the Status Log tab (newest entry by date drives this headline).","In current focus since "&TEXT('Dash Feed'!$B$18,"dd/mm/yy")&IF('Dash Feed'!$B$19="",""," (wk "&'Dash Feed'!$B$19&")")&" · set on the Status Log tab") -> In current focus since 12/10/26 (wk 10) · set on the Status Log tab
B16: ="PITCH EXPOSURE · "&IF('Dash Feed'!$H$20="","no GPS sessions logged yet",UPPER('Dash Feed'!$H$20)) -> PITCH EXPOSURE · LATEST LOGGED GPS WEEK: WK 11
B17: ='Dash Feed'!$A$24 -> Running volume | D17: ='Dash Feed'!$A$25 -> Accel / decel | G17: ='Dash Feed'!$A$26 -> Change of direction | K17: ='Dash Feed'!$A$27 -> High-speed running | M17: ='Dash Feed'!$A$28 -> Sprint distance | P17: ='Dash Feed'!$A$29 -> Top speed
B18: ='Dash Feed'!$C$24 -> 3,900 m total | D18: ='Dash Feed'!$C$25 -> 29 acc + dec | G18: ='Dash Feed'!$C$26 -> not GPS-tracked | K18: ='Dash Feed'!$C$27 -> 140 m HSR | M18: ='Dash Feed'!$C$28 -> 30 m sprint | P18: ='Dash Feed'!$C$29 -> 7.1 m/s · 80%
B19: ='Dash Feed'!$F$24 -> since 12/10/26 · wk 10 | D19: ='Dash Feed'!$F$25 -> since 19/10/26 · wk 11 | G19: ='Dash Feed'!$F$26 -> not yet introduced | K19: ='Dash Feed'!$F$27 -> not yet introduced | M19: ='Dash Feed'!$F$28 -> not yet introduced | P19: ='Dash Feed'!$F$29 -> not yet introduced
B20: ='Dash Feed'!$B$24 -> 1 | D20: ='Dash Feed'!$B$25 -> 1 | G20: ='Dash Feed'!$B$26 -> 0 | K20: ='Dash Feed'!$B$27 -> 0 | M20: ='Dash Feed'!$B$28 -> 0 | P20: ='Dash Feed'!$B$29 -> 0
B21: STAGE HISTORY · last six Status Log entries, oldest → newest
B22: ='Dash Feed'!$E$33 -> 10/08/26 · wk 1 | D22: ='Dash Feed'!$E$34 -> 14/09/26 · wk 6 | G22: ='Dash Feed'!$E$35 -> 12/10/26 · wk 10 | K22: ='Dash Feed'!$E$36 -> 19/10/26 · wk 11 | M22: ='Dash Feed'!$E$37 | P22: ='Dash Feed'!$E$38
B23: ='Dash Feed'!$G$33 -> Gym-based — strength focus | D23: ='Dash Feed'!$G$34 -> Gym-based — strength + plyometric focus | G23: ='Dash Feed'!$G$35 -> Pitch-based — linear running / volume focus | K23: ='Dash Feed'!$G$36 -> Pitch-based — linear running / volume focus + accel/decel | M23: ='Dash Feed'!$G$37 | P23: ='Dash Feed'!$G$38
B24: ='Dash Feed'!$K$33 -> Unavailable — training & fixtures | D24: ='Dash Feed'!$K$34 -> Unavailable — training & fixtures | G24: ='Dash Feed'!$K$35 -> Unavailable — training & fixtures | K24: ='Dash Feed'!$K$36 -> Unavailable — training & fixtures | M24: ='Dash Feed'!$K$37 | P24: ='Dash Feed'!$K$38
B26: Regions shown on this dashboard
B27: HIP | D27: HAMSTRING | F27: KNEE | H27: ANKLE-FOOT | K27: SHOULDER | M27: LSI TARGET | O27: CHARTS SHOW
B28: ✓ | F28: ✓ | M28: 0.9 | O28: Knee
B29: Tick (✓) the regions relevant to this player — only ticked regions appear below, stacked in this order. Clear a cell to hide that region. 'Charts show' picks the region the progression charts plot (blank = first ticked).
B31: What's open — criteria still to meet for the current phase
B32: Region | D32: Current phase | G32: Cleared | H32: Open criteria
B33: ='Dash Feed'!$C$42 -> Hip | D33: ='Dash Feed'!$D$42 -> 1. Protection | G33: ='Dash Feed'!$F$42 -> 0 / 6 | H33: ='Dash Feed'!$G$42 -> Pain ≤ 2/10 with ADLs, full weight-bearing · No night pain
B34: ='Dash Feed'!$C$43 -> Knee | D34: ='Dash Feed'!$D$43 -> 3. Specific Loading | G34: ='Dash Feed'!$F$43 -> 2 / 6 | H34: ='Dash Feed'!$G$43 -> Pain-free jogging
B35: ='Dash Feed'!$C$44 | D35: ='Dash Feed'!$D$44 | G35: ='Dash Feed'!$F$44 | H35: ='Dash Feed'!$G$44
B36: ='Dash Feed'!$C$45 | D36: ='Dash Feed'!$D$45 | G36: ='Dash Feed'!$F$45 | H36: ='Dash Feed'!$G$45
B37: ='Dash Feed'!$C$46 | D37: ='Dash Feed'!$D$46 | G37: ='Dash Feed'!$F$46 | H37: ='Dash Feed'!$G$46
B39: Latest tests · ticked regions | K39: GPS · weekly pitch load
B40: Block | C40: Test | E40: L / score | F40: R | G40: LSI | H40: Δ prev | I40: Date | L40: TD (m) | M40: HSR (m) | N40: SD (m) | O40: Acc (#) | P40: Dec (#) | Q40: Top Speed (m/s)
A41: =IF('Dash Feed'!$D$50,1,0) -> 1 | B41: ='Dash Feed'!$F$50 -> HIP | C41: ='Dash Feed'!$G$50 -> 1. Protection · 0 / 6 | E41: ='Dash Feed'!$H$50 | F41: ='Dash Feed'!$I$50 | G41: ='Dash Feed'!$J$50 | H41: ='Dash Feed'!$K$50 | I41: ='Dash Feed'!$L$50 -> 46314 | K41: Pre-injury baseline | L41: =IF(GPS!C16="","",GPS!C16) -> 20000 | M41: =IF(GPS!D16="","",GPS!D16) -> 800 | N41: =IF(GPS!E16="","",GPS!E16) -> 300 | O41: =IF(GPS!F16="","",GPS!F16) -> 80 | P41: =IF(GPS!G16="","",GPS!G16) -> 80 | Q41: =IF(GPS!H16="","",GPS!H16) -> 8.9
A42: =IF('Dash Feed'!$D$51,1,0) -> 0 | B42: ='Dash Feed'!$F$51 -> ROM | C42: ='Dash Feed'!$G$51 -> Hip Flexion (°) | E42: ='Dash Feed'!$H$51 | F42: ='Dash Feed'!$I$51 | G42: ='Dash Feed'!$J$51 | H42: ='Dash Feed'!$K$51 | I42: ='Dash Feed'!$L$51 | K42: ="Latest week"&IF('Chart Feed'!$H$49=0,""," (wk "&'Chart Feed'!$H$49&")") -> Latest week (wk 11) | L42: =IFERROR(IF(INDEX(GPS!C$20:C$71,'Chart Feed'!$H$49)="","",INDEX(GPS!C$20:C$71,'Chart Feed'!$H$49)),"") -> 3900 | M42: =IFERROR(IF(INDEX(GPS!D$20:D$71,'Chart Feed'!$H$49)="","",INDEX(GPS!D$20:D$71,'Chart Feed'!$H$49)),"") -> 140 | N42: =IFERROR(IF(INDEX(GPS!E$20:E$71,'Chart Feed'!$H$49)="","",INDEX(GPS!E$20:E$71,'Chart Feed'!$H$49)),"") -> 30 | O42: =IFERROR(IF(INDEX(GPS!F$20:F$71,'Chart Feed'!$H$49)="","",INDEX(GPS!F$20:F$71,'Chart Feed'!$H$49)),"") -> 15 | P42: =IFERROR(IF(INDEX(GPS!G$20:G$71,'Chart Feed'!$H$49)="","",INDEX(GPS!G$20:G$71,'Chart Feed'!$H$49)),"") -> 14 | Q42: =IFERROR(IF(INDEX(GPS!H$20:H$71,'Chart Feed'!$H$49)="","",INDEX(GPS!H$20:H$71,'Chart Feed'!$H$49)),"") -> 7.1
A43: =IF('Dash Feed'!$D$52,1,0) -> 0 | B43: ='Dash Feed'!$F$52 | C43: ='Dash Feed'!$G$52 -> Hip Extension (°) | E43: ='Dash Feed'!$H$52 | F43: ='Dash Feed'!$I$52 | G43: ='Dash Feed'!$J$52 | H43: ='Dash Feed'!$K$52 | I43: ='Dash Feed'!$L$52 | K43: % of baseline | L43: =IFERROR(IF(OR(L42="",L41=""),"",L42/L41),"") -> 0.195 | M43: =IFERROR(IF(OR(M42="",M41=""),"",M42/M41),"") -> 0.175 | N43: =IFERROR(IF(OR(N42="",N41=""),"",N42/N41),"") -> 0.1 | O43: =IFERROR(IF(OR(O42="",O41=""),"",O42/O41),"") -> 0.1875 | P43: =IFERROR(IF(OR(P42="",P41=""),"",P42/P41),"") -> 0.175 | Q43: =IFERROR(IF(OR(Q42="",Q41=""),"",Q42/Q41),"") -> 0.79775281
A44: =IF('Dash Feed'!$D$53,1,0) -> 0 | B44: ='Dash Feed'!$F$53 | C44: ='Dash Feed'!$G$53 -> Hip IR @ 90° (°) | E44: ='Dash Feed'!$H$53 | F44: ='Dash Feed'!$I$53 | G44: ='Dash Feed'!$J$53 | H44: ='Dash Feed'!$K$53 | I44: ='Dash Feed'!$L$53 | K44: Best week to date | L44: =IF(COUNT(GPS!C$20:C$71)=0,"",MAX(GPS!C$20:C$71)) -> 10470 | M44: =IF(COUNT(GPS!D$20:D$71)=0,"",MAX(GPS!D$20:D$71)) -> 475 | N44: =IF(COUNT(GPS!E$20:E$71)=0,"",MAX(GPS!E$20:E$71)) -> 125 | O44: =IF(COUNT(GPS!F$20:F$71)=0,"",MAX(GPS!F$20:F$71)) -> 47 | P44: =IF(COUNT(GPS!G$20:G$71)=0,"",MAX(GPS!G$20:G$71)) -> 42 | Q44: =IF(COUNT(GPS!H$20:H$71)=0,"",MAX(GPS!H$20:H$71)) -> 7.9
A45: =IF('Dash Feed'!$D$54,1,0) -> 0 | B45: ='Dash Feed'!$F$54 | C45: ='Dash Feed'!$G$54 -> Hip ER @ 90° (°) | E45: ='Dash Feed'!$H$54 | F45: ='Dash Feed'!$I$54 | G45: ='Dash Feed'!$J$54 | H45: ='Dash Feed'!$K$54 | I45: ='Dash Feed'!$L$54 | K45: Speeds in m/s. Criteria, baseline and session log on the GPS tab.
A46: =IF('Dash Feed'!$D$55,1,0) -> 0 | B46: ='Dash Feed'!$F$55 | C46: ='Dash Feed'!$G$55 -> Active Abduction (°) | E46: ='Dash Feed'!$H$55 | F46: ='Dash Feed'!$I$55 | G46: ='Dash Feed'!$J$55 | H46: ='Dash Feed'!$K$55 | I46: ='Dash Feed'!$L$55
A47: =IF('Dash Feed'!$D$56,1,0) -> 0 | B47: ='Dash Feed'!$F$56 | C47: ='Dash Feed'!$G$56 -> Passive Abduction (°) | E47: ='Dash Feed'!$H$56 | F47: ='Dash Feed'!$I$56 | G47: ='Dash Feed'!$J$56 | H47: ='Dash Feed'!$K$56 | I47: ='Dash Feed'!$L$56
A48: =IF('Dash Feed'!$D$57,1,0) -> 0 | B48: ='Dash Feed'!$F$57 -> Strength | C48: ='Dash Feed'!$G$57 -> Hip Flexion @ 90° (kg) | E48: ='Dash Feed'!$H$57 -> 22.6 | F48: ='Dash Feed'!$I$57 -> 24.3 | G48: ='Dash Feed'!$J$57 -> 0.93004115 | H48: ='Dash Feed'!$K$57 -> +9 pts | I48: ='Dash Feed'!$L$57 -> 46314
...

Sheet Status Log
A1: Status Log — availability & current focus
A2: Add a row whenever the player's availability or focus changes. The newest entry (by date) drives the Dashboard headline; the list itself is the stage history. Pitch add-ons stack — keep earlier ticks on as you add new ones.
A4: Date | B4: Wk | C4: Availability | D4: Current focus (base) | E4: Accel / decel | F4: Change of direction | G4: High-speed running | H4: Sprint distance | I4: Top speed | J4: Headline (auto) | K4: Notes
A5: 46244 | B5: =IF(A5="","",IF(Dashboard!$L$5="","",INT((A5-Dashboard!$L$5)/7)+1)) -> 1 | C5: Unavailable — training & fixtures | D5: Gym-based — strength focus | J5: =IF(OR(A5="",D5=""),"",D5&IF(COUNTA(E5:I5)=0,""," + "&_xlfn.TEXTJOIN(" + ",TRUE(),IF(E5<>"","accel/decel",""),IF(F5<>"","change of direction",""),IF(G5<>"","high-speed running",""),IF(H5<>"","sprint distance",""),IF(I5<>"","top-speed exposure","")))) -> Gym-based — strength focus | K5: EXAMPLE ROW — overwrite / delete
A6: 46279 | B6: =IF(A6="","",IF(Dashboard!$L$5="","",INT((A6-Dashboard!$L$5)/7)+1)) -> 6 | C6: Unavailable — training & fixtures | D6: Gym-based — strength + plyometric focus | J6: =IF(OR(A6="",D6=""),"",D6&IF(COUNTA(E6:I6)=0,""," + "&_xlfn.TEXTJOIN(" + ",TRUE(),IF(E6<>"","accel/decel",""),IF(F6<>"","change of direction",""),IF(G6<>"","high-speed running",""),IF(H6<>"","sprint distance",""),IF(I6<>"","top-speed exposure","")))) -> Gym-based — strength + plyometric focus | K6: EXAMPLE ROW — overwrite / delete
A7: 46307 | B7: =IF(A7="","",IF(Dashboard!$L$5="","",INT((A7-Dashboard!$L$5)/7)+1)) -> 10 | C7: Unavailable — training & fixtures | D7: Pitch-based — linear running / volume focus | J7: =IF(OR(A7="",D7=""),"",D7&IF(COUNTA(E7:I7)=0,""," + "&_xlfn.TEXTJOIN(" + ",TRUE(),IF(E7<>"","accel/decel",""),IF(F7<>"","change of direction",""),IF(G7<>"","high-speed running",""),IF(H7<>"","sprint distance",""),IF(I7<>"","top-speed exposure","")))) -> Pitch-based — linear running / volume focus | K7: EXAMPLE ROW — overwrite / delete
A8: 46314 | B8: =IF(A8="","",IF(Dashboard!$L$5="","",INT((A8-Dashboard!$L$5)/7)+1)) -> 11 | C8: Unavailable — training & fixtures | D8: Pitch-based — linear running / volume focus | E8: ✓ | J8: =IF(OR(A8="",D8=""),"",D8&IF(COUNTA(E8:I8)=0,""," + "&_xlfn.TEXTJOIN(" + ",TRUE(),IF(E8<>"","accel/decel",""),IF(F8<>"","change of direction",""),IF(G8<>"","high-speed running",""),IF(H8<>"","sprint distance",""),IF(I8<>"","top-speed exposure","")))) -> Pitch-based — linear running / volume focus + accel/decel | K8: EXAMPLE ROW — overwrite / delete
B9: =IF(A9="","",IF(Dashboard!$L$5="","",INT((A9-Dashboard!$L$5)/7)+1)) | J9: =IF(OR(A9="",D9=""),"",D9&IF(COUNTA(E9:I9)=0,""," + "&_xlfn.TEXTJOIN(" + ",TRUE(),IF(E9<>"","accel/decel",""),IF(F9<>"","change of direction",""),IF(G9<>"","high-speed running",""),IF(H9<>"","sprint distance",""),IF(I9<>"","top-speed exposure",""))))
B10: =IF(A10="","",IF(Dashboard!$L$5="","",INT((A10-Dashboard!$L$5)/7)+1)) | J10: =IF(OR(A10="",D10=""),"",D10&IF(COUNTA(E10:I10)=0,""," + "&_xlfn.TEXTJOIN(" + ",TRUE(),IF(E10<>"","accel/decel",""),IF(F10<>"","change of direction",""),IF(G10<>"","high-speed running",""),IF(H10<>"","sprint distance",""),IF(I10<>"","top-speed exposure",""))))
B11: =IF(A11="","",IF(Dashboard!$L$5="","",INT((A11-Dashboard!$L$5)/7)+1)) | J11: =IF(OR(A11="",D11=""),"",D11&IF(COUNTA(E11:I11)=0,""," + "&_xlfn.TEXTJOIN(" + ",TRUE(),IF(E11<>"","accel/decel",""),IF(F11<>"","change of direction",""),IF(G11<>"","high-speed running",""),IF(H11<>"","sprint distance",""),IF(I11<>"","top-speed exposure",""))))
B12: =IF(A12="","",IF(Dashboard!$L$5="","",INT((A12-Dashboard!$L$5)/7)+1)) | J12: =IF(OR(A12="",D12=""),"",D12&IF(COUNTA(E12:I12)=0,""," + "&_xlfn.TEXTJOIN(" + ",TRUE(),IF(E12<>"","accel/decel",""),IF(F12<>"","change of direction",""),IF(G12<>"","high-speed running",""),IF(H12<>"","sprint distance",""),IF(I12<>"","top-speed exposure",""))))
B13: =IF(A13="","",IF(Dashboard!$L$5="","",INT((A13-Dashboard!$L$5)/7)+1)) | J13: =IF(OR(A13="",D13=""),"",D13&IF(COUNTA(E13:I13)=0,""," + "&_xlfn.TEXTJOIN(" + ",TRUE(),IF(E13<>"","accel/decel",""),IF(F13<>"","change of direction",""),IF(G13<>"","high-speed running",""),IF(H13<>"","sprint distance",""),IF(I13<>"","top-speed exposure",""))))
B14: =IF(A14="","",IF(Dashboard!$L$5="","",INT((A14-Dashboard!$L$5)/7)+1)) | J14: =IF(OR(A14="",D14=""),"",D14&IF(COUNTA(E14:I14)=0,""," + "&_xlfn.TEXTJOIN(" + ",TRUE(),IF(E14<>"","accel/decel",""),IF(F14<>"","change of direction",""),IF(G14<>"","high-speed running",""),IF(H14<>"","sprint distance",""),IF(I14<>"","top-speed exposure",""))))
B15: =IF(A15="","",IF(Dashboard!$L$5="","",INT((A15-Dashboard!$L$5)/7)+1)) | J15: =IF(OR(A15="",D15=""),"",D15&IF(COUNTA(E15:I15)=0,""," + "&_xlfn.TEXTJOIN(" + ",TRUE(),IF(E15<>"","accel/decel",""),IF(F15<>"","change of direction",""),IF(G15<>"","high-speed running",""),IF(H15<>"","sprint distance",""),IF(I15<>"","top-speed exposure",""))))
B16: =IF(A16="","",IF(Dashboard!$L$5="","",INT((A16-Dashboard!$L$5)/7)+1)) | J16: =IF(OR(A16="",D16=""),"",D16&IF(COUNTA(E16:I16)=0,""," + "&_xlfn.TEXTJOIN(" + ",TRUE(),IF(E16<>"","accel/decel",""),IF(F16<>"","change of direction",""),IF(G16<>"","high-speed running",""),IF(H16<>"","sprint distance",""),IF(I16<>"","top-speed exposure",""))))
B17: =IF(A17="","",IF(Dashboard!$L$5="","",INT((A17-Dashboard!$L$5)/7)+1)) | J17: =IF(OR(A17="",D17=""),"",D17&IF(COUNTA(E17:I17)=0,""," + "&_xlfn.TEXTJOIN(" + ",TRUE(),IF(E17<>"","accel/decel",""),IF(F17<>"","change of direction",""),IF(G17<>"","high-speed running",""),IF(H17<>"","sprint distance",""),IF(I17<>"","top-speed exposure",""))))
B18: =IF(A18="","",IF(Dashboard!$L$5="","",INT((A18-Dashboard!$L$5)/7)+1)) | J18: =IF(OR(A18="",D18=""),"",D18&IF(COUNTA(E18:I18)=0,""," + "&_xlfn.TEXTJOIN(" + ",TRUE(),IF(E18<>"","accel/decel",""),IF(F18<>"","change of direction",""),IF(G18<>"","high-speed running",""),IF(H18<>"","sprint distance",""),IF(I18<>"","top-speed exposure",""))))
B19: =IF(A19="","",IF(Dashboard!$L$5="","",INT((A19-Dashboard!$L$5)/7)+1)) | J19: =IF(OR(A19="",D19=""),"",D19&IF(COUNTA(E19:I19)=0,""," + "&_xlfn.TEXTJOIN(" + ",TRUE(),IF(E19<>"","accel/decel",""),IF(F19<>"","change of direction",""),IF(G19<>"","high-speed running",""),IF(H19<>"","sprint distance",""),IF(I19<>"","top-speed exposure",""))))
B20: =IF(A20="","",IF(Dashboard!$L$5="","",INT((A20-Dashboard!$L$5)/7)+1)) | J20: =IF(OR(A20="",D20=""),"",D20&IF(COUNTA(E20:I20)=0,""," + "&_xlfn.TEXTJOIN(" + ",TRUE(),IF(E20<>"","accel/decel",""),IF(F20<>"","change of direction",""),IF(G20<>"","high-speed running",""),IF(H20<>"","sprint distance",""),IF(I20<>"","top-speed exposure",""))))
... B104: =IF(A104="","",IF(Dashboard!$L$5="","",INT((A104-Dashboard!$L$5)/7)+1)) | J104: =IF(OR(A104="",D104=""),"",D104&IF(COUNTA(E104:I104)=0,""," + "&_xlfn.TEXTJOIN(" + ",TRUE(),IF(E104<>"","accel/decel",""),IF(F104<>"","change of direction",""),IF(G104<>"","high-speed running",""),IF(H104<>"","sprint distance",""),IF(I104<>"","top-speed exposure",""))))

Sheet Hip
A1: Hip — Rehabilitation Testing
A2: Hip & groin tracker. ROM in degrees; strength = KangaTech hip profile in kg. LSI = injured ÷ uninjured side (set the Injured side tile on the Dashboard). Wk = rehab week, stamped automatically from the date.
A4: Phase Progression — Exit Criteria (live: pick test · measure · operator · threshold; Override for manual items). LSI / GPS thresholds as decimals (0.9 = 90%).
A5: # | B5: Phase | D5: Criterion (edit) | K5: Test (dropdown) | N5: Measure | O5: Op | P5: Threshold | Q5: Current (auto) | S5: Auto result | T5: Override (Y/N) | U5: Met? | V5: Date met (auto) | X5: Notes
A6: 1 | B6: 1. Protection | D6: Pain ≤ 2/10 with ADLs, full weight-bearing | K6: Manual | O6: ≥ | Q6: =IF(IF(OR($K6="",$K6="Manual"),"",IF(LEFT($K6,4)="GPS:",IFERROR(CHOOSE(MATCH($K6,Lists!$G$3:$G$8,0),GPS!$G$6,GPS!$G$7,GPS!$G$8,GPS!$G$9,GPS!$G$10,GPS!$G$11),""),IFERROR(IF($N6="LSI",INDEX($I$109:$I$132,MATCH($K6,$C$109:$C$132,0)),IF($N6="L",INDEX($G$109:$G$132,MATCH($K6,$C$109:$C$132,0)),IF($N6="R",INDEX($H$109:$H$132,MATCH($K6,$C$109:$C$132,0)),IF(Dashboard!$K$5="L",INDEX($G$109:$G$132,MATCH($K6,$C$109:$C$132,0)),IF(Dashboard!$K$5="R",INDEX($H$109:$H$132,MATCH($K6,$C$109:$C$132,0)),""))))),"")))="","",IF(OR($N6="LSI",LEFT($K6,4)="GPS:"),TEXT(IF(OR($K6="",$K6="Manual"),"",IF(LEFT($K6,4)="GPS:",IFERROR(CHOOSE(MATCH($K6,Lists!$G$3:$G$8,0),GPS!$G$6,GPS!$G$7,GPS!$G$8,GPS!$G$9,GPS!$G$10,GPS!$G$11),""),IFERROR(IF($N6="LSI",INDEX($I$109:$I$132,MATCH($K6,$C$109:$C$132,0)),IF($N6="L",INDEX($G$109:$G$132,MATCH($K6,$C$109:$C$132,0)),IF($N6="R",INDEX($H$109:$H$132,MATCH($K6,$C$109:$C$132,0)),IF(Dashboard!$K$5="L",INDEX($G$109:$G$132,MATCH($K6,$C$109:$C$132,0)),IF(Dashboard!$K$5="R",INDEX($H$109:$H$132,MATCH($K6,$C$109:$C$132,0)),""))))),""))),"0%"),TEXT(IF(OR($K6="",$K6="Manual"),"",IF(LEFT($K6,4)="GPS:",IFERROR(CHOOSE(MATCH($K6,Lists!$G$3:$G$8,0),GPS!$G$6,GPS!$G$7,GPS!$G$8,GPS!$G$9,GPS!$G$10,GPS!$G$11),""),IFERROR(IF($N6="LSI",INDEX($I$109:$I$132,MATCH($K6,$C$109:$C$132,0)),IF($N6="L",INDEX($G$109:$G$132,MATCH($K6,$C$109:$C$132,0)),IF($N6="R",INDEX($H$109:$H$132,MATCH($K6,$C$109:$C$132,0)),IF(Dashboard!$K$5="L",INDEX($G$109:$G$132,MATCH($K6,$C$109:$C$132,0)),IF(Dashboard!$K$5="R",INDEX($H$109:$H$132,MATCH($K6,$C$109:$C$132,0)),""))))),""))),"0.0"))) | S6: =IF(OR(IF(OR($K6="",$K6="Manual"),"",IF(LEFT($K6,4)="GPS:",IFERROR(CHOOSE(MATCH($K6,Lists!$G$3:$G$8,0),GPS!$G$6,GPS!$G$7,GPS!$G$8,GPS!$G$9,GPS!$G$10,GPS!$G$11),""),IFERROR(IF($N6="LSI",INDEX($I$109:$I$132,MATCH($K6,$C$109:$C$132,0)),IF($N6="L",INDEX($G$109:$G$132,MATCH($K6,$C$109:$C$132,0)),IF($N6="R",INDEX($H$109:$H$132,MATCH($K6,$C$109:$C$132,0)),IF(Dashboard!$K$5="L",INDEX($G$109:$G$132,MATCH($K6,$C$109:$C$132,0)),IF(Dashboard!$K$5="R",INDEX($H$109:$H$132,MATCH($K6,$C$109:$C$132,0)),""))))),"")))="",$P6=""),"",IF(IF($O6="≤",IF(OR($K6="",$K6="Manual"),"",IF(LEFT($K6,4)="GPS:",IFERROR(CHOOSE(MATCH($K6,Lists!$G$3:$G$8,0),GPS!$G$6,GPS!$G$7,GPS!$G$8,GPS!$G$9,GPS!$G$10,GPS!$G$11),""),IFERROR(IF($N6="LSI",INDEX($I$109:$I$132,MATCH($K6,$C$109:$C$132,0)),IF($N6="L",INDEX($G$109:$G$132,MATCH($K6,$C$109:$C$132,0)),IF($N6="R",INDEX($H$109:$H$132,MATCH($K6,$C$109:$C$132,0)),IF(Dashboard!$K$5="L",INDEX($G$109:$G$132,MATCH($K6,$C$109:$C$132,0)),IF(Dashboard!$K$5="R",INDEX($H$109:$H$132,MATCH($K6,$C$109:$C$132,0)),""))))),"")))<=$P6,IF(OR($K6="",$K6="Manual"),"",IF(LEFT($K6,4)="GPS:",IFERROR(CHOOSE(MATCH($K6,Lists!$G$3:$G$8,0),GPS!$G$6,GPS!$G$7,GPS!$G$8,GPS!$G$9,GPS!$G$10,GPS!$G$11),""),IFERROR(IF($N6="LSI",INDEX($I$109:$I$132,MATCH($K6,$C$109:$C$132,0)),IF($N6="L",INDEX($G$109:$G$132,MATCH($K6,$C$109:$C$132,0)),IF($N6="R",INDEX($H$109:$H$132,MATCH($K6,$C$109:$C$132,0)),IF(Dashboard!$K$5="L",INDEX($G$109:$G$132,MATCH($K6,$C$109:$C$132,0)),IF(Dashboard!$K$5="R",INDEX($H$109:$H$132,MATCH($K6,$C$109:$C$132,0)),""))))),"")))>=$P6),"MET","NOT MET")) | U6: =IF($T6<>"",$T6,IF($S6="MET","Y",IF($S6="NOT MET","N",""))) | V6: =IF($U6="Y",IFERROR(IF(LEFT($K6,4)="GPS:","",INDEX($J$109:$J$132,MATCH($K6,$C$109:$C$132,0))),""),"")
A7: 2 | D7: No night pain | K7: Manual | O7: ≥ | Q7: =IF(IF(OR($K7="",$K7="Manual"),"",IF(LEFT($K7,4)="GPS:",IFERROR(CHOOSE(MATCH($K7,Lists!$G$3:$G$8,0),GPS!$G$6,GPS!$G$7,GPS!$G$8,GPS!$G$9,GPS!$G$10,GPS!$G$11),""),IFERROR(IF($N7="LSI",INDEX($I$109:$I$132,MATCH($K7,$C$109:$C$132,0)),IF($N7="L",INDEX($G$109:$G$132,MATCH($K7,$C$109:$C$132,0)),IF($N7="R",INDEX($H$109:$H$132,MATCH($K7,$C$109:$C$132,0)),IF(Dashboard!$K$5="L",INDEX($G$109:$G$132,MATCH($K7,$C$109:$C$132,0)),IF(Dashboard!$K$5="R",INDEX($H$109:$H$132,MATCH($K7,$C$109:$C$132,0)),""))))),"")))="","",IF(OR($N7="LSI",LEFT($K7,4)="GPS:"),TEXT(IF(OR($K7="",$K7="Manual"),"",IF(LEFT($K7,4)="GPS:",IFERROR(CHOOSE(MATCH($K7,Lists!$G$3:$G$8,0),GPS!$G$6,GPS!$G$7,GPS!$G$8,GPS!$G$9,GPS!$G$10,GPS!$G$11),""),IFERROR(IF($N7="LSI",INDEX($I$109:$I$132,MATCH($K7,$C$109:$C$132,0)),IF($N7="L",INDEX($G$109:$G$132,MATCH($K7,$C$109:$C$132,0)),IF($N7="R",INDEX($H$109:$H$132,MATCH($K7,$C$109:$C$132,0)),IF(Dashboard!$K$5="L",INDEX($G$109:$G$132,MATCH($K7,$C$109:$C$132,0)),IF(Dashboard!$K$5="R",INDEX($H$109:$H$132,MATCH($K7,$C$109:$C$132,0)),""))))),""))),"0%"),TEXT(IF(OR($K7="",$K7="Manual"),"",IF(LEFT($K7,4)="GPS:",IFERROR(CHOOSE(MATCH($K7,Lists!$G$3:$G$8,0),GPS!$G$6,GPS!$G$7,GPS!$G$8,GPS!$G$9,GPS!$G$10,GPS!$G$11),""),IFERROR(IF($N7="LSI",INDEX($I$109:$I$132,MATCH($K7,$C$109:$C$132,0)),IF($N7="L",INDEX($G$109:$G$132,MATCH($K7,$C$109:$C$132,0)),IF($N7="R",INDEX($H$109:$H$132,MATCH($K7,$C$109:$C$132,0)),IF(Dashboard!$K$5="L",INDEX($G$109:$G$132,MATCH($K7,$C$109:$C$132,0)),IF(Dashboard!$K$5="R",INDEX($H$109:$H$132,MATCH($K7,$C$109:$C$132,0)),""))))),""))),"0.0"))) | S7: =IF(OR(IF(OR($K7="",$K7="Manual"),"",IF(LEFT($K7,4)="GPS:",IFERROR(CHOOSE(MATCH($K7,Lists!$G$3:$G$8,0),GPS!$G$6,GPS!$G$7,GPS!$G$8,GPS!$G$9,GPS!$G$10,GPS!$G$11),""),IFERROR(IF($N7="LSI",INDEX($I$109:$I$132,MATCH($K7,$C$109:$C$132,0)),IF($N7="L",INDEX($G$109:$G$132,MATCH($K7,$C$109:$C$132,0)),IF($N7="R",INDEX($H$109:$H$132,MATCH($K7,$C$109:$C$132,0)),IF(Dashboard!$K$5="L",INDEX($G$109:$G$132,MATCH($K7,$C$109:$C$132,0)),IF(Dashboard!$K$5="R",INDEX($H$109:$H$132,MATCH($K7,$C$109:$C$132,0)),""))))),"")))="",$P7=""),"",IF(IF($O7="≤",IF(OR($K7="",$K7="Manual"),"",IF(LEFT($K7,4)="GPS:",IFERROR(CHOOSE(MATCH($K7,Lists!$G$3:$G$8,0),GPS!$G$6,GPS!$G$7,GPS!$G$8,GPS!$G$9,GPS!$G$10,GPS!$G$11),""),IFERROR(IF($N7="LSI",INDEX($I$109:$I$132,MATCH($K7,$C$109:$C$132,0)),IF($N7="L",INDEX($G$109:$G$132,MATCH($K7,$C$109:$C$132,0)),IF($N7="R",INDEX($H$109:$H$132,MATCH($K7,$C$109:$C$132,0)),IF(Dashboard!$K$5="L",INDEX($G$109:$G$132,MATCH($K7,$C$109:$C$132,0)),IF(Dashboard!$K$5="R",INDEX($H$109:$H$132,MATCH($K7,$C$109:$C$132,0)),""))))),"")))<=$P7,IF(OR($K7="",$K7="Manual"),"",IF(LEFT($K7,4)="GPS:",IFERROR(CHOOSE(MATCH($K7,Lists!$G$3:$G$8,0),GPS!$G$6,GPS!$G$7,GPS!$G$8,GPS!$G$9,GPS!$G$10,GPS!$G$11),""),IFERROR(IF($N7="LSI",INDEX($I$109:$I$132,MATCH($K7,$C$109:$C$132,0)),IF($N7="L",INDEX($G$109:$G$132,MATCH($K7,$C$109:$C$132,0)),IF($N7="R",INDEX($H$109:$H$132,MATCH($K7,$C$109:$C$132,0)),IF(Dashboard!$K$5="L",INDEX($G$109:$G$132,MATCH($K7,$C$109:$C$132,0)),IF(Dashboard!$K$5="R",INDEX($H$109:$H$132,MATCH($K7,$C$109:$C$132,0)),""))))),"")))>=$P7),"MET","NOT MET")) | U7: =IF($T7<>"",$T7,IF($S7="MET","Y",IF($S7="NOT MET","N",""))) | V7: =IF($U7="Y",IFERROR(IF(LEFT($K7,4)="GPS:","",INDEX($J$109:$J$132,MATCH($K7,$C$109:$C$132,0))),""),"")
A8: 3 | O8: ≥ | Q8: =IF(IF(OR($K8="",$K8="Manual"),"",IF(LEFT($K8,4)="GPS:",IFERROR(CHOOSE(MATCH($K8,Lists!$G$3:$G$8,0),GPS!$G$6,GPS!$G$7,GPS!$G$8,GPS!$G$9,GPS!$G$10,GPS!$G$11),""),IFERROR(IF($N8="LSI",INDEX($I$109:$I$132,MATCH($K8,$C$109:$C$132,0)),IF($N8="L",INDEX($G$109:$G$132,MATCH($K8,$C$109:$C$132,0)),IF($N8="R",INDEX($H$109:$H$132,MATCH($K8,$C$109:$C$132,0)),IF(Dashboard!$K$5="L",INDEX($G$109:$G$132,MATCH($K8,$C$109:$C$132,0)),IF(Dashboard!$K$5="R",INDEX($H$109:$H$132,MATCH($K8,$C$109:$C$132,0)),""))))),"")))="","",IF(OR($N8="LSI",LEFT($K8,4)="GPS:"),TEXT(IF(OR($K8="",$K8="Manual"),"",IF(LEFT($K8,4)="GPS:",IFERROR(CHOOSE(MATCH($K8,Lists!$G$3:$G$8,0),GPS!$G$6,GPS!$G$7,GPS!$G$8,GPS!$G$9,GPS!$G$10,GPS!$G$11),""),IFERROR(IF($N8="LSI",INDEX($I$109:$I$132,MATCH($K8,$C$109:$C$132,0)),IF($N8="L",INDEX($G$109:$G$132,MATCH($K8,$C$109:$C$132,0)),IF($N8="R",INDEX($H$109:$H$132,MATCH($K8,$C$109:$C$132,0)),IF(Dashboard!$K$5="L",INDEX($G$109:$G$132,MATCH($K8,$C$109:$C$132,0)),IF(Dashboard!$K$5="R",INDEX($H$109:$H$132,MATCH($K8,$C$109:$C$132,0)),""))))),""))),"0%"),TEXT(IF(OR($K8="",$K8="Manual"),"",IF(LEFT($K8,4)="GPS:",IFERROR(CHOOSE(MATCH($K8,Lists!$G$3:$G$8,0),GPS!$G$6,GPS!$G$7,GPS!$G$8,GPS!$G$9,GPS!$G$10,GPS!$G$11),""),IFERROR(IF($N8="LSI",INDEX($I$109:$I$132,MATCH($K8,$C$109:$C$132,0)),IF($N8="L",INDEX($G$109:$G$132,MATCH($K8,$C$109:$C$132,0)),IF($N8="R",INDEX($H$109:$H$132,MATCH($K8,$C$109:$C$132,0)),IF(Dashboard!$K$5="L",INDEX($G$109:$G$132,MATCH($K8,$C$109:$C$132,0)),IF(Dashboard!$K$5="R",INDEX($H$109:$H$132,MATCH($K8,$C$109:$C$132,0)),""))))),""))),"0.0"))) | S8: =IF(OR(IF(OR($K8="",$K8="Manual"),"",IF(LEFT($K8,4)="GPS:",IFERROR(CHOOSE(MATCH($K8,Lists!$G$3:$G$8,0),GPS!$G$6,GPS!$G$7,GPS!$G$8,GPS!$G$9,GPS!$G$10,GPS!$G$11),""),IFERROR(IF($N8="LSI",INDEX($I$109:$I$132,MATCH($K8,$C$109:$C$132,0)),IF($N8="L",INDEX($G$109:$G$132,MATCH($K8,$C$109:$C$132,0)),IF($N8="R",INDEX($H$109:$H$132,MATCH($K8,$C$109:$C$132,0)),IF(Dashboard!$K$5="L",INDEX($G$109:$G$132,MATCH($K8,$C$109:$C$132,0)),IF(Dashboard!$K$5="R",INDEX($H$109:$H$132,MATCH($K8,$C$109:$C$132,0)),""))))),"")))="",$P8=""),"",IF(IF($O8="≤",IF(OR($K8="",$K8="Manual"),"",IF(LEFT($K8,4)="GPS:",IFERROR(CHOOSE(MATCH($K8,Lists!$G$3:$G$8,0),GPS!$G$6,GPS!$G$7,GPS!$G$8,GPS!$G$9,GPS!$G$10,GPS!$G$11),""),IFERROR(IF($N8="LSI",INDEX($I$109:$I$132,MATCH($K8,$C$109:$C$132,0)),IF($N8="L",INDEX($G$109:$G$132,MATCH($K8,$C$109:$C$132,0)),IF($N8="R",INDEX($H$109:$H$132,MATCH($K8,$C$109:$C$132,0)),IF(Dashboard!$K$5="L",INDEX($G$109:$G$132,MATCH($K8,$C$109:$C$132,0)),IF(Dashboard!$K$5="R",INDEX($H$109:$H$132,MATCH($K8,$C$109:$C$132,0)),""))))),"")))<=$P8,IF(OR($K8="",$K8="Manual"),"",IF(LEFT($K8,4)="GPS:",IFERROR(CHOOSE(MATCH($K8,Lists!$G$3:$G$8,0),GPS!$G$6,GPS!$G$7,GPS!$G$8,GPS!$G$9,GPS!$G$10,GPS!$G$11),""),IFERROR(IF($N8="LSI",INDEX($I$109:$I$132,MATCH($K8,$C$109:$C$132,0)),IF($N8="L",INDEX($G$109:$G$132,MATCH($K8,$C$109:$C$132,0)),IF($N8="R",INDEX($H$109:$H$132,MATCH($K8,$C$109:$C$132,0)),IF(Dashboard!$K$5="L",INDEX($G$109:$G$132,MATCH($K8,$C$109:$C$132,0)),IF(Dashboard!$K$5="R",INDEX($H$109:$H$132,MATCH($K8,$C$109:$C$132,0)),""))))),"")))>=$P8),"MET","NOT MET")) | U8: =IF($T8<>"",$T8,IF($S8="MET","Y",IF($S8="NOT MET","N",""))) | V8: =IF($U8="Y",IFERROR(IF(LEFT($K8,4)="GPS:","",INDEX($J$109:$J$132,MATCH($K8,$C$109:$C$132,0))),""),"")
A9: 4 | B9: 2. Load Introduction | D9: Hip flexion ROM ≥ 90% of other side | K9: Hip Flexion (°) | N9: LSI | O9: ≥ | P9: 0.9 | Q9: =IF(IF(OR($K9="",$K9="Manual"),"",IF(LEFT($K9,4)="GPS:",IFERROR(CHOOSE(MATCH($K9,Lists!$G$3:$G$8,0),GPS!$G$6,GPS!$G$7,GPS!$G$8,GPS!$G$9,GPS!$G$10,GPS!$G$11),""),IFERROR(IF($N9="LSI",INDEX($I$109:$I$132,MATCH($K9,$C$109:$C$132,0)),IF($N9="L",INDEX($G$109:$G$132,MATCH($K9,$C$109:$C$132,0)),IF($N9="R",INDEX($H$109:$H$132,MATCH($K9,$C$109:$C$132,0)),IF(Dashboard!$K$5="L",INDEX($G$109:$G$132,MATCH($K9,$C$109:$C$132,0)),IF(Dashboard!$K$5="R",INDEX($H$109:$H$132,MATCH($K9,$C$109:$C$132,0)),""))))),"")))="","",IF(OR($N9="LSI",LEFT($K9,4)="GPS:"),TEXT(IF(OR($K9="",$K9="Manual"),"",IF(LEFT($K9,4)="GPS:",IFERROR(CHOOSE(MATCH($K9,Lists!$G$3:$G$8,0),GPS!$G$6,GPS!$G$7,GPS!$G$8,GPS!$G$9,GPS!$G$10,GPS!$G$11),""),IFERROR(IF($N9="LSI",INDEX($I$109:$I$132,MATCH($K9,$C$109:$C$132,0)),IF($N9="L",INDEX($G$109:$G$132,MATCH($K9,$C$109:$C$132,0)),IF($N9="R",INDEX($H$109:$H$132,MATCH($K9,$C$109:$C$132,0)),IF(Dashboard!$K$5="L",INDEX($G$109:$G$132,MATCH($K9,$C$109:$C$132,0)),IF(Dashboard!$K$5="R",INDEX($H$109:$H$132,MATCH($K9,$C$109:$C$132,0)),""))))),""))),"0%"),TEXT(IF(OR($K9="",$K9="Manual"),"",IF(LEFT($K9,4)="GPS:",IFERROR(CHOOSE(MATCH($K9,Lists!$G$3:$G$8,0),GPS!$G$6,GPS!$G$7,GPS!$G$8,GPS!$G$9,GPS!$G$10,GPS!$G$11),""),IFERROR(IF($N9="LSI",INDEX($I$109:$I$132,MATCH($K9,$C$109:$C$132,0)),IF($N9="L",INDEX($G$109:$G$132,MATCH($K9,$C$109:$C$132,0)),IF($N9="R",INDEX($H$109:$H$132,MATCH($K9,$C$109:$C$132,0)),IF(Dashboard!$K$5="L",INDEX($G$109:$G$132,MATCH($K9,$C$109:$C$132,0)),IF(Dashboard!$K$5="R",INDEX($H$109:$H$132,MATCH($K9,$C$109:$C$132,0)),""))))),""))),"0.0"))) | S9: =IF(OR(IF(OR($K9="",$K9="Manual"),"",IF(LEFT($K9,4)="GPS:",IFERROR(CHOOSE(MATCH($K9,Lists!$G$3:$G$8,0),GPS!$G$6,GPS!$G$7,GPS!$G$8,GPS!$G$9,GPS!$G$10,GPS!$G$11),""),IFERROR(IF($N9="LSI",INDEX($I$109:$I$132,MATCH($K9,$C$109:$C$132,0)),IF($N9="L",INDEX($G$109:$G$132,MATCH($K9,$C$109:$C$132,0)),IF($N9="R",INDEX($H$109:$H$132,MATCH($K9,$C$109:$C$132,0)),IF(Dashboard!$K$5="L",INDEX($G$109:$G$132,MATCH($K9,$C$109:$C$132,0)),IF(Dashboard!$K$5="R",INDEX($H$109:$H$132,MATCH($K9,$C$109:$C$132,0)),""))))),"")))="",$P9=""),"",IF(IF($O9="≤",IF(OR($K9="",$K9="Manual"),"",IF(LEFT($K9,4)="GPS:",IFERROR(CHOOSE(MATCH($K9,Lists!$G$3:$G$8,0),GPS!$G$6,GPS!$G$7,GPS!$G$8,GPS!$G$9,GPS!$G$10,GPS!$G$11),""),IFERROR(IF($N9="LSI",INDEX($I$109:$I$132,MATCH($K9,$C$109:$C$132,0)),IF($N9="L",INDEX($G$109:$G$132,MATCH($K9,$C$109:$C$132,0)),IF($N9="R",INDEX($H$109:$H$132,MATCH($K9,$C$109:$C$132,0)),IF(Dashboard!$K$5="L",INDEX($G$109:$G$132,MATCH($K9,$C$109:$C$132,0)),IF(Dashboard!$K$5="R",INDEX($H$109:$H$132,MATCH($K9,$C$109:$C$132,0)),""))))),"")))<=$P9,IF(OR($K9="",$K9="Manual"),"",IF(LEFT($K9,4)="GPS:",IFERROR(CHOOSE(MATCH($K9,Lists!$G$3:$G$8,0),GPS!$G$6,GPS!$G$7,GPS!$G$8,GPS!$G$9,GPS!$G$10,GPS!$G$11),""),IFERROR(IF($N9="LSI",INDEX($I$109:$I$132,MATCH($K9,$C$109:$C$132,0)),IF($N9="L",INDEX($G$109:$G$132,MATCH($K9,$C$109:$C$132,0)),IF($N9="R",INDEX($H$109:$H$132,MATCH($K9,$C$109:$C$132,0)),IF(Dashboard!$K$5="L",INDEX($G$109:$G$132,MATCH($K9,$C$109:$C$132,0)),IF(Dashboard!$K$5="R",INDEX($H$109:$H$132,MATCH($K9,$C$109:$C$132,0)),""))))),"")))>=$P9),"MET","NOT MET")) | U9: =IF($T9<>"",$T9,IF($S9="MET","Y",IF($S9="NOT MET","N",""))) | V9: =IF($U9="Y",IFERROR(IF(LEFT($K9,4)="GPS:","",INDEX($J$109:$J$132,MATCH($K9,$C$109:$C$132,0))),""),"")
A10: 5 | D10: Adduction @ 30° ≥ 70% LSI | K10: Adduction @ 30° (kg) | N10: LSI | O10: ≥ | P10: 0.7 | Q10: =IF(IF(OR($K10="",$K10="Manual"),"",IF(LEFT($K10,4)="GPS:",IFERROR(CHOOSE(MATCH($K10,Lists!$G$3:$G$8,0),GPS!$G$6,GPS!$G$7,GPS!$G$8,GPS!$G$9,GPS!$G$10,GPS!$G$11),""),IFERROR(IF($N10="LSI",INDEX($I$109:$I$132,MATCH($K10,$C$109:$C$132,0)),IF($N10="L",INDEX($G$109:$G$132,MATCH($K10,$C$109:$C$132,0)),IF($N10="R",INDEX($H$109:$H$132,MATCH($K10,$C$109:$C$132,0)),IF(Dashboard!$K$5="L",INDEX($G$109:$G$132,MATCH($K10,$C$109:$C$132,0)),IF(Dashboard!$K$5="R",INDEX($H$109:$H$132,MATCH($K10,$C$109:$C$132,0)),""))))),"")))="","",IF(OR($N10="LSI",LEFT($K10,4)="GPS:"),TEXT(IF(OR($K10="",$K10="Manual"),"",IF(LEFT($K10,4)="GPS:",IFERROR(CHOOSE(MATCH($K10,Lists!$G$3:$G$8,0),GPS!$G$6,GPS!$G$7,GPS!$G$8,GPS!$G$9,GPS!$G$10,GPS!$G$11),""),IFERROR(IF($N10="LSI",INDEX($I$109:$I$132,MATCH($K10,$C$109:$C$132,0)),IF($N10="L",INDEX($G$109:$G$132,MATCH($K10,$C$109:$C$132,0)),IF($N10="R",INDEX($H$109:$H$132,MATCH($K10,$C$109:$C$132,0)),IF(Dashboard!$K$5="L",INDEX($G$109:$G$132,MATCH($K10,$C$109:$C$132,0)),IF(Dashboard!$K$5="R",INDEX($H$109:$H$132,MATCH($K10,$C$109:$C$132,0)),""))))),""))),"0%"),TEXT(IF(OR($K10="",$K10="Manual"),"",IF(LEFT($K10,4)="GPS:",IFERROR(CHOOSE(MATCH($K10,Lists!$G$3:$G$8,0),GPS!$G$6,GPS!$G$7,GPS!$G$8,GPS!$G$9,GPS!$G$10,GPS!$G$11),""),IFERROR(IF($N10="LSI",INDEX($I$109:$I$132,MATCH($K10,$C$109:$C$132,0)),IF($N10="L",INDEX($G$109:$G$132,MATCH($K10,$C$109:$C$132,0)),IF($N10="R",INDEX($H$109:$H$132,MATCH($K10,$C$109:$C$132,0)),IF(Dashboard!$K$5="L",INDEX($G$109:$G$132,MATCH($K10,$C$109:$C$132,0)),IF(Dashboard!$K$5="R",INDEX($H$109:$H$132,MATCH($K10,$C$109:$C$132,0)),""))))),""))),"0.0"))) -> 92% | S10: =IF(OR(IF(OR($K10="",$K10="Manual"),"",IF(LEFT($K10,4)="GPS:",IFERROR(CHOOSE(MATCH($K10,Lists!$G$3:$G$8,0),GPS!$G$6,GPS!$G$7,GPS!$G$8,GPS!$G$9,GPS!$G$10,GPS!$G$11),""),IFERROR(IF($N10="LSI",INDEX($I$109:$I$132,MATCH($K10,$C$109:$C$132,0)),IF($N10="L",INDEX($G$109:$G$132,MATCH($K10,$C$109:$C$132,0)),IF($N10="R",INDEX($H$109:$H$132,MATCH($K10,$C$109:$C$132,0)),IF(Dashboard!$K$5="L",INDEX($G$109:$G$132,MATCH($K10,$C$109:$C$132,0)),IF(Dashboard!$K$5="R",INDEX($H$109:$H$132,MATCH($K10,$C$109:$C$132,0)),""))))),"")))="",$P10=""),"",IF(IF($O10="≤",IF(OR($K10="",$K10="Manual"),"",IF(LEFT($K10,4)="GPS:",IFERROR(CHOOSE(MATCH($K10,Lists!$G$3:$G$8,0),GPS!$G$6,GPS!$G$7,GPS!$G$8,GPS!$G$9,GPS!$G$10,GPS!$G$11),""),IFERROR(IF($N10="LSI",INDEX($I$109:$I$132,MATCH($K10,$C$109:$C$132,0)),IF($N10="L",INDEX($G$109:$G$132,MATCH($K10,$C$109:$C$132,0)),IF($N10="R",INDEX($H$109:$H$132,MATCH($K10,$C$109:$C$132,0)),IF(Dashboard!$K$5="L",INDEX($G$109:$G$132,MATCH($K10,$C$109:$C$132,0)),IF(Dashboard!$K$5="R",INDEX($H$109:$H$132,MATCH($K10,$C$109:$C$132,0)),""))))),"")))<=$P10,IF(OR($K10="",$K10="Manual"),"",IF(LEFT($K10,4)="GPS:",IFERROR(CHOOSE(MATCH($K10,Lists!$G$3:$G$8,0),GPS!$G$6,GPS!$G$7,GPS!$G$8,GPS!$G$9,GPS!$G$10,GPS!$G$11),""),IFERROR(IF($N10="LSI",INDEX($I$109:$I$132,MATCH($K10,$C$109:$C$132,0)),IF($N10="L",INDEX($G$109:$G$132,MATCH($K10,$C$109:$C$132,0)),IF($N10="R",INDEX($H$109:$H$132,MATCH($K10,$C$109:$C$132,0)),IF(Dashboard!$K$5="L",INDEX($G$109:$G$132,MATCH($K10,$C$109:$C$132,0)),IF(Dashboard!$K$5="R",INDEX($H$109:$H$132,MATCH($K10,$C$109:$C$132,0)),""))))),"")))>=$P10),"MET","NOT MET")) -> MET | U10: =IF($T10<>"",$T10,IF($S10="MET","Y",IF($S10="NOT MET","N",""))) -> Y | V10: =IF($U10="Y",IFERROR(IF(LEFT($K10,4)="GPS:","",INDEX($J$109:$J$132,MATCH($K10,$C$109:$C$132,0))),""),"") -> 46314
A11: 6 | D11: Abduction @ 30° ≥ 70% LSI | K11: Abduction @ 30° (kg) | N11: LSI | O11: ≥ | P11: 0.7 | Q11: =IF(IF(OR($K11="",$K11="Manual"),"",IF(LEFT($K11,4)="GPS:",IFERROR(CHOOSE(MATCH($K11,Lists!$G$3:$G$8,0),GPS!$G$6,GPS!$G$7,GPS!$G$8,GPS!$G$9,GPS!$G$10,GPS!$G$11),""),IFERROR(IF($N11="LSI",INDEX($I$109:$I$132,MATCH($K11,$C$109:$C$132,0)),IF($N11="L",INDEX($G$109:$G$132,MATCH($K11,$C$109:$C$132,0)),IF($N11="R",INDEX($H$109:$H$132,MATCH($K11,$C$109:$C$132,0)),IF(Dashboard!$K$5="L",INDEX($G$109:$G$132,MATCH($K11,$C$109:$C$132,0)),IF(Dashboard!$K$5="R",INDEX($H$109:$H$132,MATCH($K11,$C$109:$C$132,0)),""))))),"")))="","",IF(OR($N11="LSI",LEFT($K11,4)="GPS:"),TEXT(IF(OR($K11="",$K11="Manual"),"",IF(LEFT($K11,4)="GPS:",IFERROR(CHOOSE(MATCH($K11,Lists!$G$3:$G$8,0),GPS!$G$6,GPS!$G$7,GPS!$G$8,GPS!$G$9,GPS!$G$10,GPS!$G$11),""),IFERROR(IF($N11="LSI",INDEX($I$109:$I$132,MATCH($K11,$C$109:$C$132,0)),IF($N11="L",INDEX($G$109:$G$132,MATCH($K11,$C$109:$C$132,0)),IF($N11="R",INDEX($H$109:$H$132,MATCH($K11,$C$109:$C$132,0)),IF(Dashboard!$K$5="L",INDEX($G$109:$G$132,MATCH($K11,$C$109:$C$132,0)),IF(Dashboard!$K$5="R",INDEX($H$109:$H$132,MATCH($K11,$C$109:$C$132,0)),""))))),""))),"0%"),TEXT(IF(OR($K11="",$K11="Manual"),"",IF(LEFT($K11,4)="GPS:",IFERROR(CHOOSE(MATCH($K11,Lists!$G$3:$G$8,0),GPS!$G$6,GPS!$G$7,GPS!$G$8,GPS!$G$9,GPS!$G$10,GPS!$G$11),""),IFERROR(IF($N11="LSI",INDEX($I$109:$I$132,MATCH($K11,$C$109:$C$132,0)),IF($N11="L",INDEX($G$109:$G$132,MATCH($K11,$C$109:$C$132,0)),IF($N11="R",INDEX($H$109:$H$132,MATCH($K11,$C$109:$C$132,0)),IF(Dashboard!$K$5="L",INDEX($G$109:$G$132,MATCH($K11,$C$109:$C$132,0)),IF(Dashboard!$K$5="R",INDEX($H$109:$H$132,MATCH($K11,$C$109:$C$132,0)),""))))),""))),"0.0"))) -> 93% | S11: =IF(OR(IF(OR($K11="",$K11="Manual"),"",IF(LEFT($K11,4)="GPS:",IFERROR(CHOOSE(MATCH($K11,Lists!$G$3:$G$8,0),GPS!$G$6,GPS!$G$7,GPS!$G$8,GPS!$G$9,GPS!$G$10,GPS!$G$11),""),IFERROR(IF($N11="LSI",INDEX($I$109:$I$132,MATCH($K11,$C$109:$C$132,0)),IF($N11="L",INDEX($G$109:$G$132,MATCH($K11,$C$109:$C$132,0)),IF($N11="R",INDEX($H$109:$H$132,MATCH($K11,$C$109:$C$132,0)),IF(Dashboard!$K$5="L",INDEX($G$109:$G$132,MATCH($K11,$C$109:$C$132,0)),IF(Dashboard!$K$5="R",INDEX($H$109:$H$132,MATCH($K11,$C$109:$C$132,0)),""))))),"")))="",$P11=""),"",IF(IF($O11="≤",IF(OR($K11="",$K11="Manual"),"",IF(LEFT($K11,4)="GPS:",IFERROR(CHOOSE(MATCH($K11,Lists!$G$3:$G$8,0),GPS!$G$6,GPS!$G$7,GPS!$G$8,GPS!$G$9,GPS!$G$10,GPS!$G$11),""),IFERROR(IF($N11="LSI",INDEX($I$109:$I$132,MATCH($K11,$C$109:$C$132,0)),IF($N11="L",INDEX($G$109:$G$132,MATCH($K11,$C$109:$C$132,0)),IF($N11="R",INDEX($H$109:$H$132,MATCH($K11,$C$109:$C$132,0)),IF(Dashboard!$K$5="L",INDEX($G$109:$G$132,MATCH($K11,$C$109:$C$132,0)),IF(Dashboard!$K$5="R",INDEX($H$109:$H$132,MATCH($K11,$C$109:$C$132,0)),""))))),"")))<=$P11,IF(OR($K11="",$K11="Manual"),"",IF(LEFT($K11,4)="GPS:",IFERROR(CHOOSE(MATCH($K11,Lists!$G$3:$G$8,0),GPS!$G$6,GPS!$G$7,GPS!$G$8,GPS!$G$9,GPS!$G$10,GPS!$G$11),""),IFERROR(IF($N11="LSI",INDEX($I$109:$I$132,MATCH($K11,$C$109:$C$132,0)),IF($N11="L",INDEX($G$109:$G$132,MATCH($K11,$C$109:$C$132,0)),IF($N11="R",INDEX($H$109:$H$132,MATCH($K11,$C$109:$C$132,0)),IF(Dashboard!$K$5="L",INDEX($G$109:$G$132,MATCH($K11,$C$109:$C$132,0)),IF(Dashboard!$K$5="R",INDEX($H$109:$H$132,MATCH($K11,$C$109:$C$132,0)),""))))),"")))>=$P11),"MET","NOT MET")) -> MET | U11: =IF($T11<>"",$T11,IF($S11="MET","Y",IF($S11="NOT MET","N",""))) -> Y | V11: =IF($U11="Y",IFERROR(IF(LEFT($K11,4)="GPS:","",INDEX($J$109:$J$132,MATCH($K11,$C$109:$C$132,0))),""),"") -> 46314
A12: 7 | B12: 3. Specific Loading | D12: Adduction @ 30° ≥ 80% LSI | K12: Adduction @ 30° (kg) | N12: LSI | O12: ≥ | P12: 0.8 | Q12: =IF(IF(OR($K12="",$K12="Manual"),"",IF(LEFT($K12,4)="GPS:",IFERROR(CHOOSE(MATCH($K12,Lists!$G$3:$G$8,0),GPS!$G$6,GPS!$G$7,GPS!$G$8,GPS!$G$9,GPS!$G$10,GPS!$G$11),""),IFERROR(IF($N12="LSI",INDEX($I$109:$I$132,MATCH($K12,$C$109:$C$132,0)),IF($N12="L",INDEX($G$109:$G$132,MATCH($K12,$C$109:$C$132,0)),IF($N12="R",INDEX($H$109:$H$132,MATCH($K12,$C$109:$C$132,0)),IF(Dashboard!$K$5="L",INDEX($G$109:$G$132,MATCH($K12,$C$109:$C$132,0)),IF(Dashboard!$K$5="R",INDEX($H$109:$H$132,MATCH($K12,$C$109:$C$132,0)),""))))),"")))="","",IF(OR($N12="LSI",LEFT($K12,4)="GPS:"),TEXT(IF(OR($K12="",$K12="Manual"),"",IF(LEFT($K12,4)="GPS:",IFERROR(CHOOSE(MATCH($K12,Lists!$G$3:$G$8,0),GPS!$G$6,GPS!$G$7,GPS!$G$8,GPS!$G$9,GPS!$G$10,GPS!$G$11),""),IFERROR(IF($N12="LSI",INDEX($I$109:$I$132,MATCH($K12,$C$109:$C$132,0)),IF($N12="L",INDEX($G$109:$G$132,MATCH($K12,$C$109:$C$132,0)),IF($N12="R",INDEX($H$109:$H$132,MATCH($K12,$C$109:$C$132,0)),IF(Dashboard!$K$5="L",INDEX($G$109:$G$132,MATCH($K12,$C$109:$C$132,0)),IF(Dashboard!$K$5="R",INDEX($H$109:$H$132,MATCH($K12,$C$109:$C$132,0)),""))))),""))),"0%"),TEXT(IF(OR($K12="",$K12="Manual"),"",IF(LEFT($K12,4)="GPS:",IFERROR(CHOOSE(MATCH($K12,Lists!$G$3:$G$8,0),GPS!$G$6,GPS!$G$7,GPS!$G$8,GPS!$G$9,GPS!$G$10,GPS!$G$11),""),IFERROR(IF($N12="LSI",INDEX($I$109:$I$132,MATCH($K12,$C$109:$C$132,0)),IF($N12="L",INDEX($G$109:$G$132,MATCH($K12,$C$109:$C$132,0)),IF($N12="R",INDEX($H$109:$H$132,MATCH($K12,$C$109:$C$132,0)),IF(Dashboard!$K$5="L",INDEX($G$109:$G$132,MATCH($K12,$C$109:$C$132,0)),IF(Dashboard!$K$5="R",INDEX($H$109:$H$132,MATCH($K12,$C$109:$C$132,0)),""))))),""))),"0.0"))) -> 92% | S12: =IF(OR(IF(OR($K12="",$K12="Manual"),"",IF(LEFT($K12,4)="GPS:",IFERROR(CHOOSE(MATCH($K12,Lists!$G$3:$G$8,0),GPS!$G$6,GPS!$G$7,GPS!$G$8,GPS!$G$9,GPS!$G$10,GPS!$G$11),""),IFERROR(IF($N12="LSI",INDEX($I$109:$I$132,MATCH($K12,$C$109:$C$132,0)),IF($N12="L",INDEX($G$109:$G$132,MATCH($K12,$C$109:$C$132,0)),IF($N12="R",INDEX($H$109:$H$132,MATCH($K12,$C$109:$C$132,0)),IF(Dashboard!$K$5="L",INDEX($G$109:$G$132,MATCH($K12,$C$109:$C$132,0)),IF(Dashboard!$K$5="R",INDEX($H$109:$H$132,MATCH($K12,$C$109:$C$132,0)),""))))),"")))="",$P12=""),"",IF(IF($O12="≤",IF(OR($K12="",$K12="Manual"),"",IF(LEFT($K12,4)="GPS:",IFERROR(CHOOSE(MATCH($K12,Lists!$G$3:$G$8,0),GPS!$G$6,GPS!$G$7,GPS!$G$8,GPS!$G$9,GPS!$G$10,GPS!$G$11),""),IFERROR(IF($N12="LSI",INDEX($I$109:$I$132,MATCH($K12,$C$109:$C$132,0)),IF($N12="L",INDEX($G$109:$G$132,MATCH($K12,$C$109:$C$132,0)),IF($N12="R",INDEX($H$109:$H$132,MATCH($K12,$C$109:$C$132,0)),IF(Dashboard!$K$5="L",INDEX($G$109:$G$132,MATCH($K12,$C$109:$C$132,0)),IF(Dashboard!$K$5="R",INDEX($H$109:$H$132,MATCH($K12,$C$109:$C$132,0)),""))))),"")))<=$P12,IF(OR($K12="",$K12="Manual"),"",IF(LEFT($K12,4)="GPS:",IFERROR(CHOOSE(MATCH($K12,Lists!$G$3:$G$8,0),GPS!$G$6,GPS!$G$7,GPS!$G$8,GPS!$G$9,GPS!$G$10,GPS!$G$11),""),IFERROR(IF($N12="LSI",INDEX($I$109:$I$132,MATCH($K12,$C$109:$C$132,0)),IF($N12="L",INDEX($G$109:$G$132,MATCH($K12,$C$109:$C$132,0)),IF($N12="R",INDEX($H$109:$H$132,MATCH($K12,$C$109:$C$132,0)),IF(Dashboard!$K$5="L",INDEX($G$109:$G$132,MATCH($K12,$C$109:$C$132,0)),IF(Dashboard!$K$5="R",INDEX($H$109:$H$132,MATCH($K12,$C$109:$C$132,0)),""))))),"")))>=$P12),"MET","NOT MET")) -> MET | U12: =IF($T12<>"",$T12,IF($S12="MET","Y",IF($S12="NOT MET","N",""))) -> Y | V12: =IF($U12="Y",IFERROR(IF(LEFT($K12,4)="GPS:","",INDEX($J$109:$J$132,MATCH($K12,$C$109:$C$132,0))),""),"") -> 46314
A13: 8 | D13: Hip flexion @ 90° ≥ 80% LSI | K13: Hip Flexion @ 90° (kg) | N13: LSI | O13: ≥ | P13: 0.8 | Q13: =IF(IF(OR($K13="",$K13="Manual"),"",IF(LEFT($K13,4)="GPS:",IFERROR(CHOOSE(MATCH($K13,Lists!$G$3:$G$8,0),GPS!$G$6,GPS!$G$7,GPS!$G$8,GPS!$G$9,GPS!$G$10,GPS!$G$11),""),IFERROR(IF($N13="LSI",INDEX($I$109:$I$132,MATCH($K13,$C$109:$C$132,0)),IF($N13="L",INDEX($G$109:$G$132,MATCH($K13,$C$109:$C$132,0)),IF($N13="R",INDEX($H$109:$H$132,MATCH($K13,$C$109:$C$132,0)),IF(Dashboard!$K$5="L",INDEX($G$109:$G$132,MATCH($K13,$C$109:$C$132,0)),IF(Dashboard!$K$5="R",INDEX($H$109:$H$132,MATCH($K13,$C$109:$C$132,0)),""))))),"")))="","",IF(OR($N13="LSI",LEFT($K13,4)="GPS:"),TEXT(IF(OR($K13="",$K13="Manual"),"",IF(LEFT($K13,4)="GPS:",IFERROR(CHOOSE(MATCH($K13,Lists!$G$3:$G$8,0),GPS!$G$6,GPS!$G$7,GPS!$G$8,GPS!$G$9,GPS!$G$10,GPS!$G$11),""),IFERROR(IF($N13="LSI",INDEX($I$109:$I$132,MATCH($K13,$C$109:$C$132,0)),IF($N13="L",INDEX($G$109:$G$132,MATCH($K13,$C$109:$C$132,0)),IF($N13="R",INDEX($H$109:$H$132,MATCH($K13,$C$109:$C$132,0)),IF(Dashboard!$K$5="L",INDEX($G$109:$G$132,MATCH($K13,$C$109:$C$132,0)),IF(Dashboard!$K$5="R",INDEX($H$109:$H$132,MATCH($K13,$C$109:$C$132,0)),""))))),""))),"0%"),TEXT(IF(OR($K13="",$K13="Manual"),"",IF(LEFT($K13,4)="GPS:",IFERROR(CHOOSE(MATCH($K13,Lists!$G$3:$G$8,0),GPS!$G$6,GPS!$G$7,GPS!$G$8,GPS!$G$9,GPS!$G$10,GPS!$G$11),""),IFERROR(IF($N13="LSI",INDEX($I$109:$I$132,MATCH($K13,$C$109:$C$132,0)),IF($N13="L",INDEX($G$109:$G$132,MATCH($K13,$C$109:$C$132,0)),IF($N13="R",INDEX($H$109:$H$132,MATCH($K13,$C$109:$C$132,0)),IF(Dashboard!$K$5="L",INDEX($G$109:$G$132,MATCH($K13,$C$109:$C$132,0)),IF(Dashboard!$K$5="R",INDEX($H$109:$H$132,MATCH($K13,$C$109:$C$132,0)),""))))),""))),"0.0"))) -> 93% | S13: =IF(OR(IF(OR($K13="",$K13="Manual"),"",IF(LEFT($K13,4)="GPS:",IFERROR(CHOOSE(MATCH($K13,Lists!$G$3:$G$8,0),GPS!$G$6,GPS!$G$7,GPS!$G$8,GPS!$G$9,GPS!$G$10,GPS!$G$11),""),IFERROR(IF($N13="LSI",INDEX($I$109:$I$132,MATCH($K13,$C$109:$C$132,0)),IF($N13="L",INDEX($G$109:$G$132,MATCH($K13,$C$109:$C$132,0)),IF($N13="R",INDEX($H$109:$H$132,MATCH($K13,$C$109:$C$132,0)),IF(Dashboard!$K$5="L",INDEX($G$109:$G$132,MATCH($K13,$C$109:$C$132,0)),IF(Dashboard!$K$5="R",INDEX($H$109:$H$132,MATCH($K13,$C$109:$C$132,0)),""))))),"")))="",$P13=""),"",IF(IF($O13="≤",IF(OR($K13="",$K13="Manual"),"",IF(LEFT($K13,4)="GPS:",IFERROR(CHOOSE(MATCH($K13,Lists!$G$3:$G$8,0),GPS!$G$6,GPS!$G$7,GPS!$G$8,GPS!$G$9,GPS!$G$10,GPS!$G$11),""),IFERROR(IF($N13="LSI",INDEX($I$109:$I$132,MATCH($K13,$C$109:$C$132,0)),IF($N13="L",INDEX($G$109:$G$132,MATCH($K13,$C$109:$C$132,0)),IF($N13="R",INDEX($H$109:$H$132,MATCH($K13,$C$109:$C$132,0)),IF(Dashboard!$K$5="L",INDEX($G$109:$G$132,MATCH($K13,$C$109:$C$132,0)),IF(Dashboard!$K$5="R",INDEX($H$109:$H$132,MATCH($K13,$C$109:$C$132,0)),""))))),"")))<=$P13,IF(OR($K13="",$K13="Manual"),"",IF(LEFT($K13,4)="GPS:",IFERROR(CHOOSE(MATCH($K13,Lists!$G$3:$G$8,0),GPS!$G$6,GPS!$G$7,GPS!$G$8,GPS!$G$9,GPS!$G$10,GPS!$G$11),""),IFERROR(IF($N13="LSI",INDEX($I$109:$I$132,MATCH($K13,$C$109:$C$132,0)),IF($N13="L",INDEX($G$109:$G$132,MATCH($K13,$C$109:$C$132,0)),IF($N13="R",INDEX($H$109:$H$132,MATCH($K13,$C$109:$C$132,0)),IF(Dashboard!$K$5="L",INDEX($G$109:$G$132,MATCH($K13,$C$109:$C$132,0)),IF(Dashboard!$K$5="R",INDEX($H$109:$H$132,MATCH($K13,$C$109:$C$132,0)),""))))),"")))>=$P13),"MET","NOT MET")) -> MET | U13: =IF($T13<>"",$T13,IF($S13="MET","Y",IF($S13="NOT MET","N",""))) -> Y | V13: =IF($U13="Y",IFERROR(IF(LEFT($K13,4)="GPS:","",INDEX($J$109:$J$132,MATCH($K13,$C$109:$C$132,0))),""),"") -> 46314
A14: 9 | D14: Pain-free linear running | K14: Manual | O14: ≥ | Q14: =IF(IF(OR($K14="",$K14="Manual"),"",IF(LEFT($K14,4)="GPS:",IFERROR(CHOOSE(MATCH($K14,Lists!$G$3:$G$8,0),GPS!$G$6,GPS!$G$7,GPS!$G$8,GPS!$G$9,GPS!$G$10,GPS!$G$11),""),IFERROR(IF($N14="LSI",INDEX($I$109:$I$132,MATCH($K14,$C$109:$C$132,0)),IF($N14="L",INDEX($G$109:$G$132,MATCH($K14,$C$109:$C$132,0)),IF($N14="R",INDEX($H$109:$H$132,MATCH($K14,$C$109:$C$132,0)),IF(Dashboard!$K$5="L",INDEX($G$109:$G$132,MATCH($K14,$C$109:$C$132,0)),IF(Dashboard!$K$5="R",INDEX($H$109:$H$132,MATCH($K14,$C$109:$C$132,0)),""))))),"")))="","",IF(OR($N14="LSI",LEFT($K14,4)="GPS:"),TEXT(IF(OR($K14="",$K14="Manual"),"",IF(LEFT($K14,4)="GPS:",IFERROR(CHOOSE(MATCH($K14,Lists!$G$3:$G$8,0),GPS!$G$6,GPS!$G$7,GPS!$G$8,GPS!$G$9,GPS!$G$10,GPS!$G$11),""),IFERROR(IF($N14="LSI",INDEX($I$109:$I$132,MATCH($K14,$C$109:$C$132,0)),IF($N14="L",INDEX($G$109:$G$132,MATCH($K14,$C$109:$C$132,0)),IF($N14="R",INDEX($H$109:$H$132,MATCH($K14,$C$109:$C$132,0)),IF(Dashboard!$K$5="L",INDEX($G$109:$G$132,MATCH($K14,$C$109:$C$132,0)),IF(Dashboard!$K$5="R",INDEX($H$109:$H$132,MATCH($K14,$C$109:$C$132,0)),""))))),""))),"0%"),TEXT(IF(OR($K14="",$K14="Manual"),"",IF(LEFT($K14,4)="GPS:",IFERROR(CHOOSE(MATCH($K14,Lists!$G$3:$G$8,0),GPS!$G$6,GPS!$G$7,GPS!$G$8,GPS!$G$9,GPS!$G$10,GPS!$G$11),""),IFERROR(IF($N14="LSI",INDEX($I$109:$I$132,MATCH($K14,$C$109:$C$132,0)),IF($N14="L",INDEX($G$109:$G$132,MATCH($K14,$C$109:$C$132,0)),IF($N14="R",INDEX($H$109:$H$132,MATCH($K14,$C$109:$C$132,0)),IF(Dashboard!$K$5="L",INDEX($G$109:$G$132,MATCH($K14,$C$109:$C$132,0)),IF(Dashboard!$K$5="R",INDEX($H$109:$H$132,MATCH($K14,$C$109:$C$132,0)),""))))),""))),"0.0"))) | S14: =IF(OR(IF(OR($K14="",$K14="Manual"),"",IF(LEFT($K14,4)="GPS:",IFERROR(CHOOSE(MATCH($K14,Lists!$G$3:$G$8,0),GPS!$G$6,GPS!$G$7,GPS!$G$8,GPS!$G$9,GPS!$G$10,GPS!$G$11),""),IFERROR(IF($N14="LSI",INDEX($I$109:$I$132,MATCH($K14,$C$109:$C$132,0)),IF($N14="L",INDEX($G$109:$G$132,MATCH($K14,$C$109:$C$132,0)),IF($N14="R",INDEX($H$109:$H$132,MATCH($K14,$C$109:$C$132,0)),IF(Dashboard!$K$5="L",INDEX($G$109:$G$132,MATCH($K14,$C$109:$C$132,0)),IF(Dashboard!$K$5="R",INDEX($H$109:$H$132,MATCH($K14,$C$109:$C$132,0)),""))))),"")))="",$P14=""),"",IF(IF($O14="≤",IF(OR($K14="",$K14="Manual"),"",IF(LEFT($K14,4)="GPS:",IFERROR(CHOOSE(MATCH($K14,Lists!$G$3:$G$8,0),GPS!$G$6,GPS!$G$7,GPS!$G$8,GPS!$G$9,GPS!$G$10,GPS!$G$11),""),IFERROR(IF($N14="LSI",INDEX($I$109:$I$132,MATCH($K14,$C$109:$C$132,0)),IF($N14="L",INDEX($G$109:$G$132,MATCH($K14,$C$109:$C$132,0)),IF($N14="R",INDEX($H$109:$H$132,MATCH($K14,$C$109:$C$132,0)),IF(Dashboard!$K$5="L",INDEX($G$109:$G$132,MATCH($K14,$C$109:$C$132,0)),IF(Dashboard!$K$5="R",INDEX($H$109:$H$132,MATCH($K14,$C$109:$C$132,0)),""))))),"")))<=$P14,IF(OR($K14="",$K14="Manual"),"",IF(LEFT($K14,4)="GPS:",IFERROR(CHOOSE(MATCH($K14,Lists!$G$3:$G$8,0),GPS!$G$6,GPS!$G$7,GPS!$G$8,GPS!$G$9,GPS!$G$10,GPS!$G$11),""),IFERROR(IF($N14="LSI",INDEX($I$109:$I$132,MATCH($K14,$C$109:$C$132,0)),IF($N14="L",INDEX($G$109:$G$132,MATCH($K14,$C$109:$C$132,0)),IF($N14="R",INDEX($H$109:$H$132,MATCH($K14,$C$109:$C$132,0)),IF(Dashboard!$K$5="L",INDEX($G$109:$G$132,MATCH($K14,$C$109:$C$132,0)),IF(Dashboard!$K$5="R",INDEX($H$109:$H$132,MATCH($K14,$C$109:$C$132,0)),""))))),"")))>=$P14),"MET","NOT MET")) | U14: =IF($T14<>"",$T14,IF($S14="MET","Y",IF($S14="NOT MET","N",""))) | V14: =IF($U14="Y",IFERROR(IF(LEFT($K14,4)="GPS:","",INDEX($J$109:$J$132,MATCH($K14,$C$109:$C$132,0))),""),"")
A15: 10 | B15: 4. Performance Loading | D15: Adduction @ 30° ≥ 90% LSI | K15: Adduction @ 30° (kg) | N15: LSI | O15: ≥ | P15: 0.9 | Q15: =IF(IF(OR($K15="",$K15="Manual"),"",IF(LEFT($K15,4)="GPS:",IFERROR(CHOOSE(MATCH($K15,Lists!$G$3:$G$8,0),GPS!$G$6,GPS!$G$7,GPS!$G$8,GPS!$G$9,GPS!$G$10,GPS!$G$11),""),IFERROR(IF($N15="LSI",INDEX($I$109:$I$132,MATCH($K15,$C$109:$C$132,0)),IF($N15="L",INDEX($G$109:$G$132,MATCH($K15,$C$109:$C$132,0)),IF($N15="R",INDEX($H$109:$H$132,MATCH($K15,$C$109:$C$132,0)),IF(Dashboard!$K$5="L",INDEX($G$109:$G$132,MATCH($K15,$C$109:$C$132,0)),IF(Dashboard!$K$5="R",INDEX($H$109:$H$132,MATCH($K15,$C$109:$C$132,0)),""))))),"")))="","",IF(OR($N15="LSI",LEFT($K15,4)="GPS:"),TEXT(IF(OR($K15="",$K15="Manual"),"",IF(LEFT($K15,4)="GPS:",IFERROR(CHOOSE(MATCH($K15,Lists!$G$3:$G$8,0),GPS!$G$6,GPS!$G$7,GPS!$G$8,GPS!$G$9,GPS!$G$10,GPS!$G$11),""),IFERROR(IF($N15="LSI",INDEX($I$109:$I$132,MATCH($K15,$C$109:$C$132,0)),IF($N15="L",INDEX($G$109:$G$132,MATCH($K15,$C$109:$C$132,0)),IF($N15="R",INDEX($H$109:$H$132,MATCH($K15,$C$109:$C$132,0)),IF(Dashboard!$K$5="L",INDEX($G$109:$G$132,MATCH($K15,$C$109:$C$132,0)),IF(Dashboard!$K$5="R",INDEX($H$109:$H$132,MATCH($K15,$C$109:$C$132,0)),""))))),""))),"0%"),TEXT(IF(OR($K15="",$K15="Manual"),"",IF(LEFT($K15,4)="GPS:",IFERROR(CHOOSE(MATCH($K15,Lists!$G$3:$G$8,0),GPS!$G$6,GPS!$G$7,GPS!$G$8,GPS!$G$9,GPS!$G$10,GPS!$G$11),""),IFERROR(IF($N15="LSI",INDEX($I$109:$I$132,MATCH($K15,$C$109:$C$132,0)),IF($N15="L",INDEX($G$109:$G$132,MATCH($K15,$C$109:$C$132,0)),IF($N15="R",INDEX($H$109:$H$132,MATCH($K15,$C$109:$C$132,0)),IF(Dashboard!$K$5="L",INDEX($G$109:$G$132,MATCH($K15,$C$109:$C$132,0)),IF(Dashboard!$K$5="R",INDEX($H$109:$H$132,MATCH($K15,$C$109:$C$132,0)),""))))),""))),"0.0"))) -> 92% | S15: =IF(OR(IF(OR($K15="",$K15="Manual"),"",IF(LEFT($K15,4)="GPS:",IFERROR(CHOOSE(MATCH($K15,Lists!$G$3:$G$8,0),GPS!$G$6,GPS!$G$7,GPS!$G$8,GPS!$G$9,GPS!$G$10,GPS!$G$11),""),IFERROR(IF($N15="LSI",INDEX($I$109:$I$132,MATCH($K15,$C$109:$C$132,0)),IF($N15="L",INDEX($G$109:$G$132,MATCH($K15,$C$109:$C$132,0)),IF($N15="R",INDEX($H$109:$H$132,MATCH($K15,$C$109:$C$132,0)),IF(Dashboard!$K$5="L",INDEX($G$109:$G$132,MATCH($K15,$C$109:$C$132,0)),IF(Dashboard!$K$5="R",INDEX($H$109:$H$132,MATCH($K15,$C$109:$C$132,0)),""))))),"")))="",$P15=""),"",IF(IF($O15="≤",IF(OR($K15="",$K15="Manual"),"",IF(LEFT($K15,4)="GPS:",IFERROR(CHOOSE(MATCH($K15,Lists!$G$3:$G$8,0),GPS!$G$6,GPS!$G$7,GPS!$G$8,GPS!$G$9,GPS!$G$10,GPS!$G$11),""),IFERROR(IF($N15="LSI",INDEX($I$109:$I$132,MATCH($K15,$C$109:$C$132,0)),IF($N15="L",INDEX($G$109:$G$132,MATCH($K15,$C$109:$C$132,0)),IF($N15="R",INDEX($H$109:$H$132,MATCH($K15,$C$109:$C$132,0)),IF(Dashboard!$K$5="L",INDEX($G$109:$G$132,MATCH($K15,$C$109:$C$132,0)),IF(Dashboard!$K$5="R",INDEX($H$109:$H$132,MATCH($K15,$C$109:$C$132,0)),""))))),"")))<=$P15,IF(OR($K15="",$K15="Manual"),"",IF(LEFT($K15,4)="GPS:",IFERROR(CHOOSE(MATCH($K15,Lists!$G$3:$G$8,0),GPS!$G$6,GPS!$G$7,GPS!$G$8,GPS!$G$9,GPS!$G$10,GPS!$G$11),""),IFERROR(IF($N15="LSI",INDEX($I$109:$I$132,MATCH($K15,$C$109:$C$132,0)),IF($N15="L",INDEX($G$109:$G$132,MATCH($K15,$C$109:$C$132,0)),IF($N15="R",INDEX($H$109:$H$132,MATCH($K15,$C$109:$C$132,0)),IF(Dashboard!$K$5="L",INDEX($G$109:$G$132,MATCH($K15,$C$109:$C$132,0)),IF(Dashboard!$K$5="R",INDEX($H$109:$H$132,MATCH($K15,$C$109:$C$132,0)),""))))),"")))>=$P15),"MET","NOT MET")) -> MET | U15: =IF($T15<>"",$T15,IF($S15="MET","Y",IF($S15="NOT MET","N",""))) -> Y | V15: =IF($U15="Y",IFERROR(IF(LEFT($K15,4)="GPS:","",INDEX($J$109:$J$132,MATCH($K15,$C$109:$C$132,0))),""),"") -> 46314
A16: 11 | D16: SL CMJ ≥ 90% LSI | K16: SL CMJ Height (cm) | N16: LSI | O16: ≥ | P16: 0.9 | Q16: =IF(IF(OR($K16="",$K16="Manual"),"",IF(LEFT($K16,4)="GPS:",IFERROR(CHOOSE(MATCH($K16,Lists!$G$3:$G$8,0),GPS!$G$6,GPS!$G$7,GPS!$G$8,GPS!$G$9,GPS!$G$10,GPS!$G$11),""),IFERROR(IF($N16="LSI",INDEX($I$109:$I$132,MATCH($K16,$C$109:$C$132,0)),IF($N16="L",INDEX($G$109:$G$132,MATCH($K16,$C$109:$C$132,0)),IF($N16="R",INDEX($H$109:$H$132,MATCH($K16,$C$109:$C$132,0)),IF(Dashboard!$K$5="L",INDEX($G$109:$G$132,MATCH($K16,$C$109:$C$132,0)),IF(Dashboard!$K$5="R",INDEX($H$109:$H$132,MATCH($K16,$C$109:$C$132,0)),""))))),"")))="","",IF(OR($N16="LSI",LEFT($K16,4)="GPS:"),TEXT(IF(OR($K16="",$K16="Manual"),"",IF(LEFT($K16,4)="GPS:",IFERROR(CHOOSE(MATCH($K16,Lists!$G$3:$G$8,0),GPS!$G$6,GPS!$G$7,GPS!$G$8,GPS!$G$9,GPS!$G$10,GPS!$G$11),""),IFERROR(IF($N16="LSI",INDEX($I$109:$I$132,MATCH($K16,$C$109:$C$132,0)),IF($N16="L",INDEX($G$109:$G$132,MATCH($K16,$C$109:$C$132,0)),IF($N16="R",INDEX($H$109:$H$132,MATCH($K16,$C$109:$C$132,0)),IF(Dashboard!$K$5="L",INDEX($G$109:$G$132,MATCH($K16,$C$109:$C$132,0)),IF(Dashboard!$K$5="R",INDEX($H$109:$H$132,MATCH($K16,$C$109:$C$132,0)),""))))),""))),"0%"),TEXT(IF(OR($K16="",$K16="Manual"),"",IF(LEFT($K16,4)="GPS:",IFERROR(CHOOSE(MATCH($K16,Lists!$G$3:$G$8,0),GPS!$G$6,GPS!$G$7,GPS!$G$8,GPS!$G$9,GPS!$G$10,GPS!$G$11),""),IFERROR(IF($N16="LSI",INDEX($I$109:$I$132,MATCH($K16,$C$109:$C$132,0)),IF($N16="L",INDEX($G$109:$G$132,MATCH($K16,$C$109:$C$132,0)),IF($N16="R",INDEX($H$109:$H$132,MATCH($K16,$C$109:$C$132,0)),IF(Dashboard!$K$5="L",INDEX($G$109:$G$132,MATCH($K16,$C$109:$C$132,0)),IF(Dashboard!$K$5="R",INDEX($H$109:$H$132,MATCH($K16,$C$109:$C$132,0)),""))))),""))),"0.0"))) | S16: =IF(OR(IF(OR($K16="",$K16="Manual"),"",IF(LEFT($K16,4)="GPS:",IFERROR(CHOOSE(MATCH($K16,Lists!$G$3:$G$8,0),GPS!$G$6,GPS!$G$7,GPS!$G$8,GPS!$G$9,GPS!$G$10,GPS!$G$11),""),IFERROR(IF($N16="LSI",INDEX($I$109:$I$132,MATCH($K16,$C$109:$C$132,0)),IF($N16="L",INDEX($G$109:$G$132,MATCH($K16,$C$109:$C$132,0)),IF($N16="R",INDEX($H$109:$H$132,MATCH($K16,$C$109:$C$132,0)),IF(Dashboard!$K$5="L",INDEX($G$109:$G$132,MATCH($K16,$C$109:$C$132,0)),IF(Dashboard!$K$5="R",INDEX($H$109:$H$132,MATCH($K16,$C$109:$C$132,0)),""))))),"")))="",$P16=""),"",IF(IF($O16="≤",IF(OR($K16="",$K16="Manual"),"",IF(LEFT($K16,4)="GPS:",IFERROR(CHOOSE(MATCH($K16,Lists!$G$3:$G$8,0),GPS!$G$6,GPS!$G$7,GPS!$G$8,GPS!$G$9,GPS!$G$10,GPS!$G$11),""),IFERROR(IF($N16="LSI",INDEX($I$109:$I$132,MATCH($K16,$C$109:$C$132,0)),IF($N16="L",INDEX($G$109:$G$132,MATCH($K16,$C$109:$C$132,0)),IF($N16="R",INDEX($H$109:$H$132,MATCH($K16,$C$109:$C$132,0)),IF(Dashboard!$K$5="L",INDEX($G$109:$G$132,MATCH($K16,$C$109:$C$132,0)),IF(Dashboard!$K$5="R",INDEX($H$109:$H$132,MATCH($K16,$C$109:$C$132,0)),""))))),"")))<=$P16,IF(OR($K16="",$K16="Manual"),"",IF(LEFT($K16,4)="GPS:",IFERROR(CHOOSE(MATCH($K16,Lists!$G$3:$G$8,0),GPS!$G$6,GPS!$G$7,GPS!$G$8,GPS!$G$9,GPS!$G$10,GPS!$G$11),""),IFERROR(IF($N16="LSI",INDEX($I$109:$I$132,MATCH($K16,$C$109:$C$132,0)),IF($N16="L",INDEX($G$109:$G$132,MATCH($K16,$C$109:$C$132,0)),IF($N16="R",INDEX($H$109:$H$132,MATCH($K16,$C$109:$C$132,0)),IF(Dashboard!$K$5="L",INDEX($G$109:$G$132,MATCH($K16,$C$109:$C$132,0)),IF(Dashboard!$K$5="R",INDEX($H$109:$H$132,MATCH($K16,$C$109:$C$132,0)),""))))),"")))>=$P16),"MET","NOT MET")) | U16: =IF($T16<>"",$T16,IF($S16="MET","Y",IF($S16="NOT MET","N",""))) | V16: =IF($U16="Y",IFERROR(IF(LEFT($K16,4)="GPS:","",INDEX($J$109:$J$132,MATCH($K16,$C$109:$C$132,0))),""),"")
A17: 12 | D17: SL hop ≥ 90% LSI | K17: SL Hop Distance (cm) | N17: LSI | O17: ≥ | P17: 0.9 | Q17: =IF(IF(OR($K17="",$K17="Manual"),"",IF(LEFT($K17,4)="GPS:",IFERROR(CHOOSE(MATCH($K17,Lists!$G$3:$G$8,0),GPS!$G$6,GPS!$G$7,GPS!$G$8,GPS!$G$9,GPS!$G$10,GPS!$G$11),""),IFERROR(IF($N17="LSI",INDEX($I$109:$I$132,MATCH($K17,$C$109:$C$132,0)),IF($N17="L",INDEX($G$109:$G$132,MATCH($K17,$C$109:$C$132,0)),IF($N17="R",INDEX($H$109:$H$132,MATCH($K17,$C$109:$C$132,0)),IF(Dashboard!$K$5="L",INDEX($G$109:$G$132,MATCH($K17,$C$109:$C$132,0)),IF(Dashboard!$K$5="R",INDEX($H$109:$H$132,MATCH($K17,$C$109:$C$132,0)),""))))),"")))="","",IF(OR($N17="LSI",LEFT($K17,4)="GPS:"),TEXT(IF(OR($K17="",$K17="Manual"),"",IF(LEFT($K17,4)="GPS:",IFERROR(CHOOSE(MATCH($K17,Lists!$G$3:$G$8,0),GPS!$G$6,GPS!$G$7,GPS!$G$8,GPS!$G$9,GPS!$G$10,GPS!$G$11),""),IFERROR(IF($N17="LSI",INDEX($I$109:$I$132,MATCH($K17,$C$109:$C$132,0)),IF($N17="L",INDEX($G$109:$G$132,MATCH($K17,$C$109:$C$132,0)),IF($N17="R",INDEX($H$109:$H$132,MATCH($K17,$C$109:$C$132,0)),IF(Dashboard!$K$5="L",INDEX($G$109:$G$132,MATCH($K17,$C$109:$C$132,0)),IF(Dashboard!$K$5="R",INDEX($H$109:$H$132,MATCH($K17,$C$109:$C$132,0)),""))))),""))),"0%"),TEXT(IF(OR($K17="",$K17="Manual"),"",IF(LEFT($K17,4)="GPS:",IFERROR(CHOOSE(MATCH($K17,Lists!$G$3:$G$8,0),GPS!$G$6,GPS!$G$7,GPS!$G$8,GPS!$G$9,GPS!$G$10,GPS!$G$11),""),IFERROR(IF($N17="LSI",INDEX($I$109:$I$132,MATCH($K17,$C$109:$C$132,0)),IF($N17="L",INDEX($G$109:$G$132,MATCH($K17,$C$109:$C$132,0)),IF($N17="R",INDEX($H$109:$H$132,MATCH($K17,$C$109:$C$132,0)),IF(Dashboard!$K$5="L",INDEX($G$109:$G$132,MATCH($K17,$C$109:$C$132,0)),IF(Dashboard!$K$5="R",INDEX($H$109:$H$132,MATCH($K17,$C$109:$C$132,0)),""))))),""))),"0.0"))) | S17: =IF(OR(IF(OR($K17="",$K17="Manual"),"",IF(LEFT($K17,4)="GPS:",IFERROR(CHOOSE(MATCH($K17,Lists!$G$3:$G$8,0),GPS!$G$6,GPS!$G$7,GPS!$G$8,GPS!$G$9,GPS!$G$10,GPS!$G$11),""),IFERROR(IF($N17="LSI",INDEX($I$109:$I$132,MATCH($K17,$C$109:$C$132,0)),IF($N17="L",INDEX($G$109:$G$132,MATCH($K17,$C$109:$C$132,0)),IF($N17="R",INDEX($H$109:$H$132,MATCH($K17,$C$109:$C$132,0)),IF(Dashboard!$K$5="L",INDEX($G$109:$G$132,MATCH($K17,$C$109:$C$132,0)),IF(Dashboard!$K$5="R",INDEX($H$109:$H$132,MATCH($K17,$C$109:$C$132,0)),""))))),"")))="",$P17=""),"",IF(IF($O17="≤",IF(OR($K17="",$K17="Manual"),"",IF(LEFT($K17,4)="GPS:",IFERROR(CHOOSE(MATCH($K17,Lists!$G$3:$G$8,0),GPS!$G$6,GPS!$G$7,GPS!$G$8,GPS!$G$9,GPS!$G$10,GPS!$G$11),""),IFERROR(IF($N17="LSI",INDEX($I$109:$I$132,MATCH($K17,$C$109:$C$132,0)),IF($N17="L",INDEX($G$109:$G$132,MATCH($K17,$C$109:$C$132,0)),IF($N17="R",INDEX($H$109:$H$132,MATCH($K17,$C$109:$C$132,0)),IF(Dashboard!$K$5="L",INDEX($G$109:$G$132,MATCH($K17,$C$109:$C$132,0)),IF(Dashboard!$K$5="R",INDEX($H$109:$H$132,MATCH($K17,$C$109:$C$132,0)),""))))),"")))<=$P17,IF(OR($K17="",$K17="Manual"),"",IF(LEFT($K17,4)="GPS:",IFERROR(CHOOSE(MATCH($K17,Lists!$G$3:$G$8,0),GPS!$G$6,GPS!$G$7,GPS!$G$8,GPS!$G$9,GPS!$G$10,GPS!$G$11),""),IFERROR(IF($N17="LSI",INDEX($I$109:$I$132,MATCH($K17,$C$109:$C$132,0)),IF($N17="L",INDEX($G$109:$G$132,MATCH($K17,$C$109:$C$132,0)),IF($N17="R",INDEX($H$109:$H$132,MATCH($K17,$C$109:$C$132,0)),IF(Dashboard!$K$5="L",INDEX($G$109:$G$132,MATCH($K17,$C$109:$C$132,0)),IF(Dashboard!$K$5="R",INDEX($H$109:$H$132,MATCH($K17,$C$109:$C$132,0)),""))))),"")))>=$P17),"MET","NOT MET")) | U17: =IF($T17<>"",$T17,IF($S17="MET","Y",IF($S17="NOT MET","N",""))) | V17: =IF($U17="Y",IFERROR(IF(LEFT($K17,4)="GPS:","",INDEX($J$109:$J$132,MATCH($K17,$C$109:$C$132,0))),""),"")
